data/sample_market_events.csv
timestamp,event_type,order_id,side,quantity,price,trader_id,target_order_id,symbol
0.001,limit,L00000001,buy,227.0,99.98,MM01,,SYNTH
0.002,limit,L00000002,sell,193.0,100.02,MM01,,SYNTH
0.003,limit,L00000003,buy,235.0,99.97,MM02,,SYNTH
0.004,limit,L00000004,sell,219.0,100.03,MM02,,SYNTH
0.005,limit,L00000005,buy,159.0,99.96,MM03,,SYNTH
0.006,limit,L00000006,sell,247.0,100.04,MM03,,SYNTH
0.007,limit,L00000007,buy,226.0,99.95,MM04,,SYNTH
0.008,limit,L00000008,sell,228.0,100.05,MM04,,SYNTH
0.009000000000000001,limit,L00000009,buy,162.0,99.94,MM05,,SYNTH
0.010000000000000002,limit,L00000010,sell,195.0,100.06,MM05,,SYNTH
0.011000000000000003,limit,L00000011,buy,187.0,99.93,MM06,,SYNTH
0.012000000000000004,limit,L00000012,sell,242.0,100.07,MM06,,SYNTH
0.013000000000000005,limit,L00000013,buy,214.0,99.92,MM07,,SYNTH
0.014000000000000005,limit,L00000014,sell,232.0,100.08,MM07,,SYNTH
0.015000000000000006,limit,L00000015,buy,194.0,99.91,MM08,,SYNTH
0.016000000000000007,limit,L00000016,sell,172.0,100.09,MM08,,SYNTH
0.017000000000000008,limit,L00000017,buy,205.0,99.9,MM09,,SYNTH
0.01800000000000001,limit,L00000018,sell,156.0,100.1,MM09,,SYNTH
0.01900000000000001,limit,L00000019,buy,232.0,99.89,MM10,,SYNTH
0.02000000000000001,limit,L00000020,sell,213.0,100.11,MM10,,SYNTH
0.02100000000000001,limit,L00000021,buy,225.0,99.88,MM11,,SYNTH
0.022000000000000013,limit,L00000022,sell,185.0,100.12,MM11,,SYNTH
0.023000000000000013,limit,L00000023,buy,247.0,99.87,MM12,,SYNTH
0.024000000000000014,limit,L00000024,sell,239.0,100.13,MM12,,SYNTH
0.025000000000000015,limit,L00000025,buy,227.0,99.86,MM13,,SYNTH
0.026000000000000016,limit,L00000026,sell,169.0,100.14,MM13,,SYNTH
0.027000000000000017,limit,L00000027,buy,196.0,99.85,MM14,,SYNTH
0.028000000000000018,limit,L00000028,sell,154.0,100.15,MM14,,SYNTH
0.02900000000000002,limit,L00000029,buy,165.0,99.84,MM15,,SYNTH
0.03000000000000002,limit,L00000030,sell,218.0,100.16,MM15,,SYNTH
0.049434011807991084,limit,L00000031,buy,40.0,99.95,T12,,SYNTH
0.11611913305958527,market,M00000032,sell,70.0,,TAKER03,,SYNTH
0.12440592842466518,market,M00000033,sell,46.0,,TAKER06,,SYNTH
0.14247303957141083,market,M00000034,sell,72.0,,TAKER07,,SYNTH
0.19464761367024103,market,M00000035,buy,18.0,,TAKER05,,SYNTH
0.24088872542637974,market,M00000036,sell,47.0,,TAKER04,,SYNTH
0.2467728413301341,limit,L00000037,buy,94.0,100.03,T12,,SYNTH
0.26323495113016937,limit,L00000038,buy,27.0,99.98,T12,,SYNTH
0.36555656738682624,limit,L00000039,buy,28.0,99.98,T04,,SYNTH
0.37495151713735037,market,M00000040,sell,37.0,,TAKER06,,SYNTH
0.38349901366028166,limit,L00000041,buy,119.0,99.99,T12,,SYNTH
0.3857910845115872,limit,L00000042,sell,55.0,100.05,T15,,SYNTH
0.4194708934173693,cancel,C00000043,,,,T14,L00000006,SYNTH
0.4584257527979997,limit,L00000044,buy,75.0,99.99,T20,,SYNTH
0.6286302176326733,market,M00000045,sell,136.0,,TAKER11,,SYNTH
0.64302865961997,limit,L00000046,sell,127.0,100.03,T15,,SYNTH
0.6708578115081378,modify,R00000047,,185.0,99.98,T22,L00000021,SYNTH
0.7302253921597373,limit,L00000048,sell,181.0,100.08,T03,,SYNTH
0.8522487215153419,limit,L00000049,buy,24.0,100.0,T15,,SYNTH
0.8744540203054164,limit,L00000050,buy,105.0,100.0,T04,,SYNTH
0.9086661498159361,market,M00000051,sell,14.0,,TAKER05,,SYNTH
0.9213048010912018,cancel,C00000052,,,,T13,L00000005,SYNTH
0.9912421830783273,limit,L00000053,buy,299.0,99.97,T11,,SYNTH
1.0629066449809272,limit,L00000054,buy,38.0,99.99,T20,,SYNTH
1.160865509555132,limit,L00000055,buy,61.0,99.98,T11,,SYNTH
1.29435985779825,limit,L00000056,sell,49.0,100.12,T02,,SYNTH
1.3179150427543758,limit,L00000057,buy,17.0,100.0,T04,,SYNTH
1.3238071413025114,limit,L00000058,sell,69.0,100.13,T08,,SYNTH
1.3511393593241312,limit,L00000059,buy,34.0,100.02,T10,,SYNTH
1.4296337672363832,limit,L00000060,sell,92.0,100.18,T21,,SYNTH
1.5890206137046237,limit,L00000061,buy,175.0,100.07,T13,,SYNTH
1.6068988322694238,limit,L00000062,sell,14.0,100.15,T06,,SYNTH
1.6666535995237153,cancel,C00000063,,,,T12,L00000055,SYNTH
1.6986591756372529,limit,L00000064,sell,36.0,100.17,T16,,SYNTH
1.7498097359049862,limit,L00000065,sell,111.0,100.15,T18,,SYNTH
1.758863498906882,market,M00000066,sell,21.0,,TAKER08,,SYNTH
1.7619157945903474,limit,L00000067,sell,83.0,100.19,T23,,SYNTH
1.8091931324555162,limit,L00000068,buy,87.0,100.08,T23,,SYNTH
1.9228338002332968,limit,L00000069,buy,59.0,100.08,T24,,SYNTH
2.078186374724473,cancel,C00000070,,,,T09,L00000010,SYNTH
2.1024905464232804,limit,L00000071,sell,273.0,100.26,T03,,SYNTH
2.16195123381761,limit,L00000072,sell,20.0,100.29,T12,,SYNTH
2.1790201157428624,limit,L00000073,sell,23.0,100.24,T21,,SYNTH
2.1800773248053567,limit,L00000074,sell,30.0,100.19,T22,,SYNTH
2.180524047423585,market,M00000075,buy,32.0,,TAKER01,,SYNTH
2.27993159702467,limit,L00000076,buy,38.0,100.16,T03,,SYNTH
2.387687196143843,limit,L00000077,buy,125.0,100.14,T18,,SYNTH
2.39241171355011,limit,L00000078,sell,26.0,100.17,T03,,SYNTH
2.4812215583225337,cancel,C00000079,,,,T08,L00000041,SYNTH
2.6512205923422445,limit,L00000080,buy,141.0,100.11,T10,,SYNTH
2.6524942141610874,limit,L00000081,sell,20.0,100.23,T10,,SYNTH
2.7008952705065123,limit,L00000082,buy,86.0,100.14,T14,,SYNTH
2.7062820064817927,limit,L00000083,buy,310.0,100.14,T20,,SYNTH
2.715707638529152,limit,L00000084,sell,31.0,100.26,T01,,SYNTH
2.7166894919147375,limit,L00000085,buy,127.0,100.18,T22,,SYNTH
2.827016807156663,limit,L00000086,sell,286.0,100.21,T11,,SYNTH
2.923305192934432,limit,L00000087,buy,86.0,100.18,T18,,SYNTH
2.9361772939728024,limit,L00000088,sell,168.0,100.21,T08,,SYNTH
2.9846876941561105,cancel,C00000089,,,,T23,L00000008,SYNTH
3.013202772547394,limit,L00000090,sell,11.0,100.21,T21,,SYNTH
3.084298841278668,limit,L00000091,buy,107.0,100.15,T08,,SYNTH
3.1603150607363335,market,M00000092,sell,15.0,,TAKER06,,SYNTH
3.1832747971153066,limit,L00000093,sell,112.0,100.22,T09,,SYNTH
3.3910357591468254,limit,L00000094,buy,76.0,100.17,T17,,SYNTH
3.424810823289717,cancel,C00000095,,,,T19,L00000061,SYNTH
3.597070536045588,market,M00000096,sell,78.0,,TAKER11,,SYNTH
3.633925035649124,modify,R00000097,,10.0,100.25,T12,L00000073,SYNTH
3.6656348669122107,market,M00000098,sell,92.0,,TAKER11,,SYNTH
3.669456263624937,market,M00000099,sell,112.0,,TAKER01,,SYNTH
3.676714381312012,market,M00000100,sell,93.0,,TAKER08,,SYNTH
3.7965578193609035,limit,L00000101,sell,8.0,100.27,T03,,SYNTH
3.86624608609781,market,M00000102,sell,263.0,,TAKER04,,SYNTH
3.912944055281139,cancel,C00000103,,,,T12,L00000020,SYNTH
3.930309392089412,limit,L00000104,buy,150.0,100.1,T16,,SYNTH
4.008042105308611,limit,L00000105,sell,94.0,100.23,T08,,SYNTH
4.069113992600586,limit,L00000106,buy,280.0,100.14,T04,,SYNTH
4.079905166271224,market,M00000107,sell,41.0,,TAKER02,,SYNTH
4.0858918590255,limit,L00000108,buy,4.0,100.13,T08,,SYNTH
4.16148554801725,limit,L00000109,buy,26.0,100.17,T19,,SYNTH
4.245701081452924,limit,L00000110,buy,109.0,100.16,T04,,SYNTH
4.2695651875955285,market,M00000111,sell,58.0,,TAKER01,,SYNTH
4.301149463522168,cancel,C00000112,,,,T02,L00000054,SYNTH
4.406198875818124,cancel,C00000113,,,,T01,L00000011,SYNTH
4.409839308873296,limit,L00000114,buy,9.0,100.16,T15,,SYNTH
4.420662523894311,limit,L00000115,sell,26.0,100.19,T23,,SYNTH
4.445100936769978,limit,L00000116,sell,112.0,100.23,T10,,SYNTH
4.445632592015523,market,M00000117,sell,174.0,,TAKER02,,SYNTH
4.5030940345113075,limit,L00000118,buy,96.0,100.14,T24,,SYNTH
4.600597198394526,limit,L00000119,sell,52.0,100.17,T07,,SYNTH
4.605849732404145,limit,L00000120,sell,103.0,100.22,T21,,SYNTH
4.785152086098873,market,M00000121,sell,15.0,,TAKER11,,SYNTH
4.786132286615143,cancel,C00000122,,,,T16,L00000062,SYNTH
4.818916773323888,market,M00000123,buy,82.0,,TAKER05,,SYNTH
4.981961961520526,market,M00000124,sell,198.0,,TAKER09,,SYNTH
5.009254964801617,limit,L00000125,sell,332.0,100.25,T20,,SYNTH
5.106463479699674,limit,L00000126,sell,195.0,100.28,T13,,SYNTH
5.1174919565634305,market,M00000127,buy,22.0,,TAKER06,,SYNTH
5.318040605830895,limit,L00000128,buy,96.0,100.22,T12,,SYNTH
5.33487745475091,limit,L00000129,buy,92.0,100.18,T08,,SYNTH
